<?xml version="1.0" encoding="utf-8"?>
<!-- This URDF was automatically created by SolidWorks to URDF Exporter! Originally created by Stephen Brawner (brawner@gmail.com) 
     Commit Version: 1.6.0-4-g7f85cfe  Build Version: 1.6.7995.38578
     For more information, please see http://wiki.ros.org/sw_urdf_exporter -->
<robot
  name="delta">
  <link name="world"/>
  <joint
    name="world_base_link"
    type="fixed">
    <parent
      link="world" />
    <child
      link="base_link" />
  </joint>
  <link
    name="base_link">
    <inertial>
      <origin
        xyz="0.380382316067151 -0.533525806735634 0.659302816292224"
        rpy="0 0 0" />
      <mass
        value="156.163072577183" />
      <inertia
        ixx="7.59889681143528"
        ixy="9.24660486508239E-05"
        ixz="-0.000259409545018871"
        iyy="7.59824264740178"
        iyz="0.000102275137498633"
        izz="10.3617884952824" />
    </inertial>
    <visual>
      <origin
        xyz="0 0 0"
        rpy="0 0 0" />
      <geometry>
        <mesh
          filename="package://delta/meshes/base_link.STL" />
      </geometry>
      <material
        name="">
        <color
          rgba="1 1 1 1" />
      </material>
    </visual>
    <collision>
      <origin
        xyz="0 0 0"
        rpy="0 0 0" />
      <geometry>
        <mesh
          filename="package://delta/meshes/base_link.STL" />
      </geometry>
    </collision>
  </link>
  <link
    name="arm1u_link">
    <inertial>
      <origin
        xyz="0.114792252146981 0.00182152585989626 0.0495423331065887"
        rpy="0 0 0" />
      <mass
        value="0.646884412038515" />
      <inertia
        ixx="0.000166776951356192"
        ixy="-0.000187543246495443"
        ixz="-4.04262175310576E-09"
        iyy="0.00675559133337473"
        iyz="6.15021017819242E-11"
        izz="0.00677709143476231" />
    </inertial>
    <visual>
      <origin
        xyz="0 0 0"
        rpy="0 0 0" />
      <geometry>
        <mesh
          filename="package://delta/meshes/arm1u_link.STL" />
      </geometry>
      <material
        name="">
        <color
          rgba="1 1 1 1" />
      </material>
    </visual>
    <collision>
      <origin
        xyz="0 0 0"
        rpy="0 0 0" />
      <geometry>
        <mesh
          filename="package://delta/meshes/arm1u_link.STL" />
      </geometry>
    </collision>
  </link>
  <joint
    name="arm1u_joint"
    type="revolute">
    <origin
      xyz="0.332874358144467 -0.683521580995339 0.398756986704061"
      rpy="-1.5707963267949 0 -1.5707963267949" />
    <parent
      link="base_link" />
    <child
      link="arm1u_link" />
    <axis
      xyz="0 0 1" />
    <limit
      lower="0"
      upper="3.1416"
      effort="0"
      velocity="0" />
  </joint>
  <link
    name="arm11_link">
    <inertial>
      <origin
        xyz="-0.0151005260811973 0.196287921564387 -0.336929572799235"
        rpy="0 0 0" />
      <mass
        value="0.127460758319217" />
      <inertia
        ixx="0.00814693140460583"
        ixy="-4.92928019985575E-05"
        ixz="9.05596189880381E-05"
        iyy="0.0062881494959543"
        iyz="0.0034190184061498"
        izz="0.00186356030148952" />
    </inertial>
    <visual>
      <origin
        xyz="0.0205 -0.005 -0.012"
        rpy="0 0 0" />
      <geometry>
        <mesh
          filename="package://delta/meshes/arm11_link.STL" />
      </geometry>
      <material
        name="">
        <color
          rgba="1 1 1 1" />
      </material>
    </visual>
    <collision>
      <origin
        xyz="0 0 0"
        rpy="0 0 0" />
      <geometry>
        <mesh
          filename="package://delta/meshes/arm11_link.STL" />
      </geometry>
    </collision>
  </link>
  <joint
    name="arm11_joint"
    type="revolute">
    <origin
      xyz="0.285 0.028 0.007"
      rpy="1.5708 -1.5708 0" />
    <parent
      link="arm1u_link" />
    <child
      link="arm11_link" />
    <axis
      xyz="1 0 0" />
    <limit
      lower="-1"
      upper="1"
      effort="0"
      velocity="0" />
  </joint>
  <link
    name="arm11_spider_link">
    <inertial>
      <origin
        xyz="0.016 0.0550000002696336 0.00234510079557038"
        rpy="0 0 0" />
      <mass
        value="0.207397112440021" />
      <inertia
        ixx="0.000172568881403432"
        ixy="-4.07679263921255E-19"
        ixz="-4.12890466512252E-20"
        iyy="0.00017256884108883"
        iyz="3.89811473984236E-13"
        izz="0.000277154102529209" />
    </inertial>
    <visual>
      <origin
        xyz="0.017 0 0.002"
        rpy="0 0 0" />
      <geometry>
        <mesh
          filename="package://delta/meshes/arm11_spider_link.STL" />
      </geometry>
      <material
        name="">
        <color
          rgba="0.898039215686275 0.917647058823529 0.929411764705882 1" />
      </material>
    </visual>
    <collision>
      <origin
        xyz="0 0 0"
        rpy="0 0 0" />
      <geometry>
        <mesh
          filename="package://delta/meshes/arm11_spider_link.STL" />
      </geometry>
    </collision>
  </link>
  <joint
    name="arm11_spider_joint"
    type="continuous">
    <origin
      xyz="0.01 0.38 -0.695"
      rpy="0 0 0" />
    <parent
      link="arm11_link" />
    <child
      link="arm11_spider_link" />
    <axis
      xyz="1 0 0" />
  </joint>
  <link
    name="arm12_link">
    <inertial>
      <origin
        xyz="0.0149009633527306 0.196209132849916 -0.33696955808221"
        rpy="0 0 0" />
      <mass
        value="0.127460758197968" />
      <inertia
        ixx="0.00814692981417886"
        ixy="4.92940499340967E-05"
        ixz="-9.05589094550425E-05"
        iyy="0.0062881507189424"
        iyz="0.00341901905662901"
        izz="0.00186356064655539" />
    </inertial>
    <visual>
      <origin
        xyz="-0.0205 -0.005 -0.012"
        rpy="0 0 0" />
      <geometry>
        <mesh
          filename="package://delta/meshes/arm12_link.STL" />
      </geometry>
      <material
        name="">
        <color
          rgba="1 1 1 1" />
      </material>
    </visual>
    <collision>
      <origin
        xyz="0 0 0"
        rpy="0 0 0" />
      <geometry>
        <mesh
          filename="package://delta/meshes/arm12_link.STL" />
      </geometry>
    </collision>
  </link>
  <joint
    name="arm12_joint"
    type="revolute">
    <origin
      xyz="0.285 0.028 0.088"
      rpy="1.5708 -1.5708 0" />
    <parent
      link="arm1u_link" />
    <child
      link="arm12_link" />
    <axis
      xyz="1 0 0" />
    <limit
      lower="-1"
      upper="1"
      effort="0"
      velocity="0" />
  </joint>
  <link
    name="arm2u_link">
    <inertial>
      <origin
        xyz="0.114792190956305 -0.00182152531048957 -0.0251673198673808"
        rpy="0 0 0" />
      <mass
        value="0.646883970811699" />
      <inertia
        ixx="0.000166776836705843"
        ixy="0.000187543268799503"
        ixz="3.21501578687261E-09"
        iyy="0.00675558779094133"
        iyz="3.68581727496335E-11"
        izz="0.00677708810261762" />
    </inertial>
    <visual>
      <origin
        xyz="0 0 0"
        rpy="0 0 0" />
      <geometry>
        <mesh
          filename="package://delta/meshes/arm2u_link.STL" />
      </geometry>
      <material
        name="">
        <color
          rgba="1 1 1 1" />
      </material>
    </visual>
    <collision>
      <origin
        xyz="0 0 0"
        rpy="0 0 0" />
      <geometry>
        <mesh
          filename="package://delta/meshes/arm2u_link.STL" />
      </geometry>
    </collision>
  </link>
  <joint
    name="arm2u_joint"
    type="revolute">
    <origin
      xyz="0.26203 -0.43849 0.39876"
      rpy="1.5708 0 2.618" />
    <parent
      link="base_link" />
    <child
      link="arm2u_link" />
    <axis
      xyz="0 0 1" />
    <limit
      lower="-3.1416"
      upper="0"
      effort="0"
      velocity="0" />
  </joint>
  <link
    name="arm21_link">
    <inertial>
      <origin
        xyz="-0.0149337877385725 0.196173393877676 -0.33698948069346"
        rpy="0 0 0" />
      <mass
        value="0.127460758272507" />
      <inertia
        ixx="0.00814690103546067"
        ixy="-4.92996198580384E-05"
        ixz="9.05557693323212E-05"
        iyy="0.00628817272220904"
        iyz="0.00341903127869353"
        izz="0.00186356743546608" />
    </inertial>
    <visual>
      <origin
        xyz="0.0205 -0.005 -0.012"
        rpy="0 0 0" />
      <geometry>
        <mesh
          filename="package://delta/meshes/arm21_link.STL" />
      </geometry>
      <material
        name="">
        <color
          rgba="1 1 1 1" />
      </material>
    </visual>
    <collision>
      <origin
        xyz="0 0 0"
        rpy="0 0 0" />
      <geometry>
        <mesh
          filename="package://delta/meshes/arm21_link.STL" />
      </geometry>
    </collision>
  </link>
  <joint
    name="arm21_joint"
    type="revolute">
    <origin
      xyz="0.285 -0.028 0.017375"
      rpy="-1.5708 1.5708 0" />
    <parent
      link="arm2u_link" />
    <child
      link="arm21_link" />
    <axis
      xyz="1 0 0" />
    <limit
      lower="-1"
      upper="1"
      effort="0"
      velocity="0" />
  </joint>
  <link
    name="arm22_link">
    <inertial>
      <origin
        xyz="0.0150335623413876 0.196158983361336 -0.336998756966697"
        rpy="0 0 0" />
      <mass
        value="0.127460758697646" />
      <inertia
        ixx="0.00814688379562211"
        ixy="4.92563063294823E-05"
        ixz="-9.05786464641641E-05"
        iyy="0.00628818562513337"
        iyz="0.00341903885912145"
        izz="0.00186357184839554" />
    </inertial>
    <visual>
      <origin
        xyz="-0.0205 -0.005 -0.012"
        rpy="0 0 0" />
      <geometry>
        <mesh
          filename="package://delta/meshes/arm22_link.STL" />
      </geometry>
      <material
        name="">
        <color
          rgba="1 1 1 1" />
      </material>
    </visual>
    <collision>
      <origin
        xyz="0 0 0"
        rpy="0 0 0" />
      <geometry>
        <mesh
          filename="package://delta/meshes/arm22_link.STL" />
      </geometry>
    </collision>
  </link>
  <joint
    name="arm22_joint"
    type="revolute">
    <origin
      xyz="0.285 -0.028 -0.063625"
      rpy="-1.5708 1.5708 0" />
    <parent
      link="arm2u_link" />
    <child
      link="arm22_link" />
    <axis
      xyz="1 0 0" />
    <limit
      lower="-1"
      upper="1"
      effort="0"
      velocity="0" />
  </joint>
  <link
    name="arm3u_link">
    <inertial>
      <origin
        xyz="0.114792221305797 -0.00182152765219995 0.184356660884915"
        rpy="0 0 0" />
      <mass
        value="0.646884127953808" />
      <inertia
        ixx="0.000166777031838413"
        ixy="0.000187543435284817"
        ixz="4.36611667900175E-09"
        iyy="0.00675559025398927"
        iyz="7.91226247931834E-11"
        izz="0.00677709036650217" />
    </inertial>
    <visual>
      <origin
        xyz="0 0 0"
        rpy="0 0 0" />
      <geometry>
        <mesh
          filename="package://delta/meshes/arm3u_link.STL" />
      </geometry>
      <material
        name="">
        <color
          rgba="1 1 1 1" />
      </material>
    </visual>
    <collision>
      <origin
        xyz="0 0 0"
        rpy="0 0 0" />
      <geometry>
        <mesh
          filename="package://delta/meshes/arm3u_link.STL" />
      </geometry>
    </collision>
  </link>
  <joint
    name="arm3u_joint"
    type="revolute">
    <origin
      xyz="0.417078668164106 -0.297095310806117 0.398756986704061"
      rpy="1.5707963267949 0 0.523598775598305" />
    <parent
      link="base_link" />
    <child
      link="arm3u_link" />
    <axis
      xyz="0 0 1" />
    <limit
      lower="-3.1416"
      upper="0"
      effort="0"
      velocity="0" />
  </joint>
  <link
    name="arm31_link">
    <inertial>
      <origin
        xyz="-0.0149753633398072 0.196343241690027 -0.336897668988324"
        rpy="0 0 0" />
      <mass
        value="0.127460758755479" />
      <inertia
        ixx="0.00814688104191047"
        ixy="-4.92603272500584E-05"
        ixz="9.05764137202415E-05"
        iyy="0.00628818782208854"
        iyz="0.00341903997839666"
        izz="0.00186357241522575" />
    </inertial>
    <visual>
      <origin
        xyz="0.0205 -0.005 -0.012"
        rpy="0 0 0" />
      <geometry>
        <mesh
          filename="package://delta/meshes/arm31_link.STL" />
      </geometry>
      <material
        name="">
        <color
          rgba="1 1 1 1" />
      </material>
    </visual>
    <collision>
      <origin
        xyz="0 0 0"
        rpy="0 0 0" />
      <geometry>
        <mesh
          filename="package://delta/meshes/arm31_link.STL" />
      </geometry>
    </collision>
  </link>
  <joint
    name="arm31_joint"
    type="revolute">
    <origin
      xyz="0.285 -0.028 0.2269"
      rpy="-1.5708 1.5708 0" />
    <parent
      link="arm3u_link" />
    <child
      link="arm31_link" />
    <axis
      xyz="1 0 0" />
    <limit
      lower="-1"
      upper="1"
      effort="0"
      velocity="0" />
  </joint>
  <link
    name="arm32_link">
    <inertial>
      <origin
        xyz="0.015109117469074 0.196251933598046 -0.33694927538221"
        rpy="0 0 0" />
      <mass
        value="0.127460758699228" />
      <inertia
        ixx="0.00814694099722032"
        ixy="4.9273743599918E-05"
        ixz="-9.05702265426356E-05"
        iyy="0.00628814155657333"
        iyz="0.00341901478439211"
        izz="0.0018635587153562" />
    </inertial>
    <visual>
      <origin
        xyz="-0.0205 -0.005 -0.012"
        rpy="0 0 0" />
      <geometry>
        <mesh
          filename="package://delta/meshes/arm32_link.STL" />
      </geometry>
      <material
        name="">
        <color
          rgba="1 1 1 1" />
      </material>
    </visual>
    <collision>
      <origin
        xyz="0 0 0"
        rpy="0 0 0" />
      <geometry>
        <mesh
          filename="package://delta/meshes/arm32_link.STL" />
      </geometry>
    </collision>
  </link>
  <joint
    name="arm32_joint"
    type="revolute">
    <origin
      xyz="0.285 -0.028 0.1459"
      rpy="-1.5708 1.5708 0" />
    <parent
      link="arm3u_link" />
    <child
      link="arm32_link" />
    <axis
      xyz="1 0 0" />
    <limit
      lower="-1"
      upper="1"
      effort="0"
      velocity="0" />
  </joint>
</robot>