<sdf version='1.7'>
  <model name='delta'>
    <link name='base_link'>
      <inertial>
        <pose>0.380382 -0.533526 0.659303 0 0 0</pose>
        <mass>156.163</mass>
        <inertia>
          <ixx>7.5989</ixx>
          <ixy>9.2466e-05</ixy>
          <ixz>-0.00025941</ixz>
          <iyy>7.59824</iyy>
          <iyz>0.000102275</iyz>
          <izz>10.3618</izz>
        </inertia>
      </inertial>
      <collision name='base_link_collision'>
        <pose>0 0 0 0 0 0</pose>
        <geometry>
          <mesh>
            <scale>1 1 1</scale>
            <uri>model://delta/meshes/base_link.STL</uri>
          </mesh>
        </geometry>
      </collision>
      <visual name='base_link_visual'>
        <pose>0 0 0 0 0 0</pose>
        <geometry>
          <mesh>
            <scale>1 1 1</scale>
            <uri>model://delta/meshes/base_link.STL</uri>
          </mesh>
        </geometry>
      </visual>
      <kinematic>true</kinematic>
    </link>
    <joint name='arm1u_joint' type='revolute'>
      <pose relative_to='base_link'>0.332874 -0.683522 0.398757 -1.5708 0 -1.5708</pose>
      <parent>base_link</parent>
      <child>arm1u_link</child>
      <axis>
        <xyz>0 0 1</xyz>
        <limit>
          <lower>0</lower>
          <upper>3.1416</upper>
          <effort>0</effort>
          <velocity>0</velocity>
        </limit>
        <dynamics>
          <spring_reference>0</spring_reference>
          <spring_stiffness>0</spring_stiffness>
        </dynamics>
      </axis>
    </joint>
    <link name='arm1u_link'>
      <pose relative_to='arm1u_joint'>0 0 0 0 0 0</pose>
      <inertial>
        <pose>0.114792 0.001822 0.049542 0 0 0</pose>
        <mass>0.646884</mass>
        <inertia>
          <ixx>0.000166777</ixx>
          <ixy>-0.000187543</ixy>
          <ixz>-4.04262e-09</ixz>
          <iyy>0.00675559</iyy>
          <iyz>6.15021e-11</iyz>
          <izz>0.00677709</izz>
        </inertia>
      </inertial>
      <collision name='arm1u_link_collision'>
        <pose>0 0 0 0 0 0</pose>
        <geometry>
          <mesh>
            <scale>1 1 1</scale>
            <uri>model://delta/meshes/arm1u_link.STL</uri>
          </mesh>
        </geometry>
      </collision>
      <visual name='arm1u_link_visual'>
        <pose>0 0 0 0 0 0</pose>
        <geometry>
          <mesh>
            <scale>1 1 1</scale>
            <uri>model://delta/meshes/arm1u_link.STL</uri>
          </mesh>
        </geometry>
      </visual>
    </link>
    <joint name='arm11_joint' type='ball'>
      <pose relative_to='arm1u_link'>0.285 0.028 0.007 -1.57079 -1.57079 -3.14159</pose>
      <parent>arm1u_link</parent>
      <child>arm11_link</child>
    </joint>
    <link name='arm11_link'>
      <pose relative_to='arm11_joint'>0 0 0 0 0 0</pose>
      <inertial>
        <pose>0.0055 0.1848 -0.33693 0 0 0</pose>
        <mass>0.127461</mass>
        <inertia>
          <ixx>0.00814693</ixx>
          <ixy>-4.92928e-05</ixy>
          <ixz>9.05596e-05</ixz>
          <iyy>0.00628815</iyy>
          <iyz>0.00341902</iyz>
          <izz>0.00186356</izz>
        </inertia>
      </inertial>
      <collision name='arm11_link_collision'>
        <pose>0.0205 -0.005 -0.012 0 0 0</pose>
        <geometry>
          <mesh>
            <scale>1 1 1</scale>
            <uri>model://delta/meshes/arm11_link.STL</uri>
          </mesh>
        </geometry>
      </collision>
      <visual name='arm11_link_visual'>
        <pose>0.0205 -0.005 -0.012 0 0 0</pose>
        <geometry>
          <mesh>
            <scale>1 1 1</scale>
            <uri>model://delta/meshes/arm11_link.STL</uri>
          </mesh>
        </geometry>
      </visual>
    </link>
    <joint name='arm11_spider_joint' type='ball'>
      <pose relative_to='arm11_joint'>0.01 0.38 -0.695 0 0 0</pose>
      <parent>arm11_link</parent>
      <child>spider_link</child>
    </joint>
    <joint name='arm12_spider_joint' type='ball'>
      <pose relative_to='arm12_joint'>-0.01 0.38 -0.695 0 0 0</pose>
      <parent>arm12_link</parent>
      <child>spider_link</child>
    </joint>
    <joint name='arm21_spider_joint' type='ball'>
      <pose relative_to='arm21_joint'>0.01 0.38 -0.695 0 0 0</pose>
      <parent>arm21_link</parent>
      <child>spider_link</child>
    </joint>
    <joint name='arm22_spider_joint' type='ball'>
      <pose relative_to='arm22_joint'>-0.01 0.38 -0.695 0 0 0</pose>
      <parent>arm22_link</parent>
      <child>spider_link</child>
    </joint>
    <joint name='arm31_spider_joint' type='ball'>
      <pose relative_to='arm31_joint'>0.01 0.38 -0.695 0 0 0</pose>
      <parent>arm31_link</parent>
      <child>spider_link</child>
    </joint>
    <joint name='arm32_spider_joint' type='ball'>
      <pose relative_to='arm32_joint'>-0.01 0.38 -0.695 0 0 0</pose>
      <parent>arm32_link</parent>
      <child>spider_link</child>
    </joint>
    <link name='spider_link'>
      <pose relative_to='arm11_spider_joint'>0 0 0 0 0 0</pose>
      <inertial>
        <pose>0.032 0.055 0.002345 0 0 0</pose>
        <mass>0.207397</mass>
        <inertia>
          <ixx>0.000172569</ixx>
          <ixy>-4.07679e-19</ixy>
          <ixz>-4.1289e-20</ixz>
          <iyy>0.000172569</iyy>
          <iyz>3.89811e-13</iyz>
          <izz>0.000277154</izz>
        </inertia>
      </inertial>
      <collision name='spider_link_collision'>
        <pose>0.017 0 0.002 0 0 0</pose>
        <geometry>
          <mesh>
            <scale>1 1 1</scale>
            <uri>model://delta/meshes/arm11_spider_link.STL</uri>
          </mesh>
        </geometry>
      </collision>
      <visual name='spider_link_visual'>
        <pose>0.017 0 0.002 0 0 0</pose>
        <geometry>
          <mesh>
            <scale>1 1 1</scale>
            <uri>model://delta/meshes/arm11_spider_link.STL</uri>
          </mesh>
        </geometry>
      </visual>
    </link>
    <joint name='arm12_joint' type='ball'>
      <pose relative_to='arm1u_link'>0.285 0.028 0.088 -1.57079 -1.57079 -3.14159</pose>
      <parent>arm1u_link</parent>
      <child>arm12_link</child>
    </joint>
    <link name='arm12_link'>
      <pose relative_to='arm12_joint'>0 0 0 0 0 0</pose>
      <inertial>
        <pose>-0.005 0.186209 -0.33697 0 0 0</pose>
        <mass>0.127461</mass>
        <inertia>
          <ixx>0.00814693</ixx>
          <ixy>4.9294e-05</ixy>
          <ixz>-9.05589e-05</ixz>
          <iyy>0.00628815</iyy>
          <iyz>0.00341902</iyz>
          <izz>0.00186356</izz>
        </inertia>
      </inertial>
      <collision name='arm12_link_collision'>
        <pose>-0.0205 -0.005 -0.012 0 0 0</pose>
        <geometry>
          <mesh>
            <scale>1 1 1</scale>
            <uri>model://delta/meshes/arm12_link.STL</uri>
          </mesh>
        </geometry>
      </collision>
      <visual name='arm12_link_visual'>
        <pose>-0.0205 -0.005 -0.012 0 0 0</pose>
        <geometry>
          <mesh>
            <scale>1 1 1</scale>
            <uri>model://delta/meshes/arm12_link.STL</uri>
          </mesh>
        </geometry>
      </visual>
    </link>
    <joint name='arm2u_joint' type='revolute'>
      <pose relative_to='base_link'>0.26203 -0.43849 0.39876 1.5708 0 2.618</pose>
      <parent>base_link</parent>
      <child>arm2u_link</child>
      <axis>
        <xyz>0 0 1</xyz>
        <limit>
          <lower>-3.1416</lower>
          <upper>0</upper>
          <effort>0</effort>
          <velocity>0</velocity>
        </limit>
        <dynamics>
          <spring_reference>0</spring_reference>
          <spring_stiffness>0</spring_stiffness>
        </dynamics>
      </axis>
    </joint>
    <link name='arm2u_link'>
      <pose relative_to='arm2u_joint'>0 0 0 0 0 0</pose>
      <inertial>
        <pose>0.114792 -0.001822 -0.025167 0 0 0</pose>
        <mass>0.646884</mass>
        <inertia>
          <ixx>0.000166777</ixx>
          <ixy>0.000187543</ixy>
          <ixz>3.21502e-09</ixz>
          <iyy>0.00675559</iyy>
          <iyz>3.68582e-11</iyz>
          <izz>0.00677709</izz>
        </inertia>
      </inertial>
      <collision name='arm2u_link_collision'>
        <pose>0 0 0 0 0 0</pose>
        <geometry>
          <mesh>
            <scale>1 1 1</scale>
            <uri>model://delta/meshes/arm2u_link.STL</uri>
          </mesh>
        </geometry>
      </collision>
      <visual name='arm2u_link_visual'>
        <pose>0 0 0 0 0 0</pose>
        <geometry>
          <mesh>
            <scale>1 1 1</scale>
            <uri>model://delta/meshes/arm2u_link.STL</uri>
          </mesh>
        </geometry>
      </visual>
    </link>
    <joint name='arm21_joint' type='ball'>
      <pose relative_to='arm2u_link'>0.285 -0.028 0.017375 1.57079 1.57079 -3.14159</pose>
      <parent>arm2u_link</parent>
      <child>arm21_link</child>
    </joint>
    <link name='arm21_link'>
      <pose relative_to='arm21_joint'>0 0 0 0 0 0</pose>
      <inertial>
        <pose>0.005 0.186173 -0.336989 0 0 0</pose>
        <mass>0.127461</mass>
        <inertia>
          <ixx>0.0081469</ixx>
          <ixy>-4.92996e-05</ixy>
          <ixz>9.05558e-05</ixz>
          <iyy>0.00628817</iyy>
          <iyz>0.00341903</iyz>
          <izz>0.00186357</izz>
        </inertia>
      </inertial>
      <collision name='arm21_link_collision'>
        <pose>0.0205 -0.005 -0.012 0 0 0</pose>
        <geometry>
          <mesh>
            <scale>1 1 1</scale>
            <uri>model://delta/meshes/arm21_link.STL</uri>
          </mesh>
        </geometry>
      </collision>
      <visual name='arm21_link_visual'>
        <pose>0.0205 -0.005 -0.012 0 0 0</pose>
        <geometry>
          <mesh>
            <scale>1 1 1</scale>
            <uri>model://delta/meshes/arm21_link.STL</uri>
          </mesh>
        </geometry>
      </visual>
    </link>
    <joint name='arm22_joint' type='ball'>
      <pose relative_to='arm2u_link'>0.285 -0.028 -0.063625 1.57079 1.57079 -3.14159</pose>
      <parent>arm2u_link</parent>
      <child>arm22_link</child>
    </joint>
    <link name='arm22_link'>
      <pose relative_to='arm22_joint'>0 0 0 0 0 0</pose>
      <inertial>
        <pose>-0.005 0.186159 -0.336999 0 0 0</pose>
        <mass>0.127461</mass>
        <inertia>
          <ixx>0.00814688</ixx>
          <ixy>4.92563e-05</ixy>
          <ixz>-9.05786e-05</ixz>
          <iyy>0.00628819</iyy>
          <iyz>0.00341904</iyz>
          <izz>0.00186357</izz>
        </inertia>
      </inertial>
      <collision name='arm22_link_collision'>
        <pose>-0.0205 -0.005 -0.012 0 0 0</pose>
        <geometry>
          <mesh>
            <scale>1 1 1</scale>
            <uri>model://delta/meshes/arm22_link.STL</uri>
          </mesh>
        </geometry>
      </collision>
      <visual name='arm22_link_visual'>
        <pose>-0.0205 -0.005 -0.012 0 0 0</pose>
        <geometry>
          <mesh>
            <scale>1 1 1</scale>
            <uri>model://delta/meshes/arm22_link.STL</uri>
          </mesh>
        </geometry>
      </visual>
    </link>
    <joint name='arm3u_joint' type='revolute'>
      <pose relative_to='base_link'>0.417079 -0.297095 0.398757 1.5708 0 0.523599</pose>
      <parent>base_link</parent>
      <child>arm3u_link</child>
      <axis>
        <xyz>0 0 1</xyz>
        <limit>
          <lower>-3.1416</lower>
          <upper>0</upper>
          <effort>0</effort>
          <velocity>0</velocity>
        </limit>
        <dynamics>
          <spring_reference>0</spring_reference>
          <spring_stiffness>0</spring_stiffness>
        </dynamics>
      </axis>
    </joint>
    <link name='arm3u_link'>
      <pose relative_to='arm3u_joint'>0 0 0 0 0 0</pose>
      <inertial>
        <pose>0.114792 -0.001822 0.184357 0 0 0</pose>
        <mass>0.646884</mass>
        <inertia>
          <ixx>0.000166777</ixx>
          <ixy>0.000187543</ixy>
          <ixz>4.36612e-09</ixz>
          <iyy>0.00675559</iyy>
          <iyz>7.91226e-11</iyz>
          <izz>0.00677709</izz>
        </inertia>
      </inertial>
      <collision name='arm3u_link_collision'>
        <pose>0 0 0 0 0 0</pose>
        <geometry>
          <mesh>
            <scale>1 1 1</scale>
            <uri>model://delta/meshes/arm3u_link.STL</uri>
          </mesh>
        </geometry>
      </collision>
      <visual name='arm3u_link_visual'>
        <pose>0 0 0 0 0 0</pose>
        <geometry>
          <mesh>
            <scale>1 1 1</scale>
            <uri>model://delta/meshes/arm3u_link.STL</uri>
          </mesh>
        </geometry>
      </visual>
    </link>
    <joint name='arm31_joint' type='ball'>
      <pose relative_to='arm3u_link'>0.285 -0.028 0.2269 1.57079 1.57079 -3.14159</pose>
      <parent>arm3u_link</parent>
      <child>arm31_link</child>
    </joint>
    <link name='arm31_link'>
      <pose relative_to='arm31_joint'>0 0 0 0 0 0</pose>
      <inertial>
        <pose>0.005 0.186343 -0.336898 0 0 0</pose>
        <mass>0.127461</mass>
        <inertia>
          <ixx>0.00814688</ixx>
          <ixy>-4.92603e-05</ixy>
          <ixz>9.05764e-05</ixz>
          <iyy>0.00628819</iyy>
          <iyz>0.00341904</iyz>
          <izz>0.00186357</izz>
        </inertia>
      </inertial>
      <collision name='arm31_link_collision'>
        <pose>0.0205 -0.005 -0.012 0 0 0</pose>
        <geometry>
          <mesh>
            <scale>1 1 1</scale>
            <uri>model://delta/meshes/arm31_link.STL</uri>
          </mesh>
        </geometry>
      </collision>
      <visual name='arm31_link_visual'>
        <pose>0.0205 -0.005 -0.012 0 0 0</pose>
        <geometry>
          <mesh>
            <scale>1 1 1</scale>
            <uri>model://delta/meshes/arm31_link.STL</uri>
          </mesh>
        </geometry>
      </visual>
    </link>
    <joint name='arm32_joint' type='ball'>
      <pose relative_to='arm3u_link'>0.285 -0.028 0.1459 1.57079 1.57079 -3.14159</pose>
      <parent>arm3u_link</parent>
      <child>arm32_link</child>
    </joint>
    <link name='arm32_link'>
      <pose relative_to='arm32_joint'>0 0 0 0 0 0</pose>
      <inertial>
        <pose>-0.005 0.186252 -0.336949 0 0 0</pose>
        <mass>0.127461</mass>
        <inertia>
          <ixx>0.00814694</ixx>
          <ixy>4.92737e-05</ixy>
          <ixz>-9.05702e-05</ixz>
          <iyy>0.00628814</iyy>
          <iyz>0.00341901</iyz>
          <izz>0.00186356</izz>
        </inertia>
      </inertial>
      <collision name='arm32_link_collision'>
        <pose>-0.0205 -0.005 -0.012 0 0 0</pose>
        <geometry>
          <mesh>
            <scale>1 1 1</scale>
            <uri>model://delta/meshes/arm32_link.STL</uri>
          </mesh>
        </geometry>
      </collision>
      <visual name='arm32_link_visual'>
        <pose>-0.0205 -0.005 -0.012 0 0 0</pose>
        <geometry>
          <mesh>
            <scale>1 1 1</scale>
            <uri>model://delta/meshes/arm32_link.STL</uri>
          </mesh>
        </geometry>
      </visual>
    </link>
    <plugin name="delta_plugin" filename="libdelta_plugin.so"/>
  </model>
</sdf>
